2018-12-16 22:51:15,867 ERROR: Exception on /chargepage [GET] [in c:\mjp\micro\env\lib\site-packages\flask\app.py:1761]
Traceback (most recent call last):
  File "c:\mjp\micro\env\lib\site-packages\sqlalchemy\orm\relationships.py", line 2082, in _determine_joins
    consider_as_foreign_keys=consider_as_foreign_keys
  File "<string>", line 2, in join_condition
  File "c:\mjp\micro\env\lib\site-packages\sqlalchemy\sql\selectable.py", line 981, in _join_condition
    (a.description, b.description, hint))
sqlalchemy.exc.NoForeignKeysError: Can't find any foreign key relationships between 'chargetype' and 'rent'.

During handling of the above exception, another exception occurred:

Traceback (most recent call last):
  File "c:\mjp\micro\env\lib\site-packages\flask\app.py", line 2292, in wsgi_app
    response = self.full_dispatch_request()
  File "c:\mjp\micro\env\lib\site-packages\flask\app.py", line 1815, in full_dispatch_request
    rv = self.handle_user_exception(e)
  File "c:\mjp\micro\env\lib\site-packages\flask\app.py", line 1718, in handle_user_exception
    reraise(exc_type, exc_value, tb)
  File "c:\mjp\micro\env\lib\site-packages\flask\_compat.py", line 35, in reraise
    raise value
  File "c:\mjp\micro\env\lib\site-packages\flask\app.py", line 1811, in full_dispatch_request
    rv = self.preprocess_request()
  File "c:\mjp\micro\env\lib\site-packages\flask\app.py", line 2087, in preprocess_request
    rv = func()
  File "C:\MJP\micro\app\routes.py", line 15, in before_request
    if current_user.is_authenticated:
  File "c:\mjp\micro\env\lib\site-packages\werkzeug\local.py", line 347, in __getattr__
    return getattr(self._get_current_object(), name)
  File "c:\mjp\micro\env\lib\site-packages\werkzeug\local.py", line 306, in _get_current_object
    return self.__local()
  File "c:\mjp\micro\env\lib\site-packages\flask_login\utils.py", line 26, in <lambda>
    current_user = LocalProxy(lambda: _get_user())
  File "c:\mjp\micro\env\lib\site-packages\flask_login\utils.py", line 335, in _get_user
    current_app.login_manager._load_user()
  File "c:\mjp\micro\env\lib\site-packages\flask_login\login_manager.py", line 359, in _load_user
    return self.reload_user()
  File "c:\mjp\micro\env\lib\site-packages\flask_login\login_manager.py", line 321, in reload_user
    user = self.user_callback(user_id)
  File "C:\MJP\micro\app\models.py", line 50, in load_user
    return User.query.get(int(id))
  File "c:\mjp\micro\env\lib\site-packages\flask_sqlalchemy\__init__.py", line 512, in __get__
    mapper = orm.class_mapper(type)
  File "c:\mjp\micro\env\lib\site-packages\sqlalchemy\orm\base.py", line 421, in class_mapper
    mapper = _inspect_mapped_class(class_, configure=configure)
  File "c:\mjp\micro\env\lib\site-packages\sqlalchemy\orm\base.py", line 400, in _inspect_mapped_class
    mapper._configure_all()
  File "c:\mjp\micro\env\lib\site-packages\sqlalchemy\orm\mapper.py", line 1276, in _configure_all
    configure_mappers()
  File "c:\mjp\micro\env\lib\site-packages\sqlalchemy\orm\mapper.py", line 3033, in configure_mappers
    mapper._post_configure_properties()
  File "c:\mjp\micro\env\lib\site-packages\sqlalchemy\orm\mapper.py", line 1832, in _post_configure_properties
    prop.init()
  File "c:\mjp\micro\env\lib\site-packages\sqlalchemy\orm\interfaces.py", line 183, in init
    self.do_init()
  File "c:\mjp\micro\env\lib\site-packages\sqlalchemy\orm\relationships.py", line 1656, in do_init
    self._setup_join_conditions()
  File "c:\mjp\micro\env\lib\site-packages\sqlalchemy\orm\relationships.py", line 1731, in _setup_join_conditions
    can_be_synced_fn=self._columns_are_mapped
  File "c:\mjp\micro\env\lib\site-packages\sqlalchemy\orm\relationships.py", line 1998, in __init__
    self._determine_joins()
  File "c:\mjp\micro\env\lib\site-packages\sqlalchemy\orm\relationships.py", line 2103, in _determine_joins
    "specify a 'primaryjoin' expression." % self.prop)
sqlalchemy.exc.NoForeignKeysError: Could not determine join condition between parent/child tables on relationship Chargetype.charge_chargetype - there are no foreign keys linking these tables.  Ensure that referencing columns are associated with a ForeignKey or ForeignKeyConstraint, or specify a 'primaryjoin' expression.
2018-12-16 22:51:16,130 ERROR: Exception on /favicon.ico [GET] [in c:\mjp\micro\env\lib\site-packages\flask\app.py:1761]
Traceback (most recent call last):
  File "c:\mjp\micro\env\lib\site-packages\flask\app.py", line 2292, in wsgi_app
    response = self.full_dispatch_request()
  File "c:\mjp\micro\env\lib\site-packages\flask\app.py", line 1815, in full_dispatch_request
    rv = self.handle_user_exception(e)
  File "c:\mjp\micro\env\lib\site-packages\flask\app.py", line 1718, in handle_user_exception
    reraise(exc_type, exc_value, tb)
  File "c:\mjp\micro\env\lib\site-packages\flask\_compat.py", line 35, in reraise
    raise value
  File "c:\mjp\micro\env\lib\site-packages\flask\app.py", line 1811, in full_dispatch_request
    rv = self.preprocess_request()
  File "c:\mjp\micro\env\lib\site-packages\flask\app.py", line 2087, in preprocess_request
    rv = func()
  File "C:\MJP\micro\app\routes.py", line 15, in before_request
    if current_user.is_authenticated:
  File "c:\mjp\micro\env\lib\site-packages\werkzeug\local.py", line 347, in __getattr__
    return getattr(self._get_current_object(), name)
  File "c:\mjp\micro\env\lib\site-packages\werkzeug\local.py", line 306, in _get_current_object
    return self.__local()
  File "c:\mjp\micro\env\lib\site-packages\flask_login\utils.py", line 26, in <lambda>
    current_user = LocalProxy(lambda: _get_user())
  File "c:\mjp\micro\env\lib\site-packages\flask_login\utils.py", line 335, in _get_user
    current_app.login_manager._load_user()
  File "c:\mjp\micro\env\lib\site-packages\flask_login\login_manager.py", line 359, in _load_user
    return self.reload_user()
  File "c:\mjp\micro\env\lib\site-packages\flask_login\login_manager.py", line 321, in reload_user
    user = self.user_callback(user_id)
  File "C:\MJP\micro\app\models.py", line 50, in load_user
    return User.query.get(int(id))
  File "c:\mjp\micro\env\lib\site-packages\flask_sqlalchemy\__init__.py", line 512, in __get__
    mapper = orm.class_mapper(type)
  File "c:\mjp\micro\env\lib\site-packages\sqlalchemy\orm\base.py", line 421, in class_mapper
    mapper = _inspect_mapped_class(class_, configure=configure)
  File "c:\mjp\micro\env\lib\site-packages\sqlalchemy\orm\base.py", line 400, in _inspect_mapped_class
    mapper._configure_all()
  File "c:\mjp\micro\env\lib\site-packages\sqlalchemy\orm\mapper.py", line 1276, in _configure_all
    configure_mappers()
  File "c:\mjp\micro\env\lib\site-packages\sqlalchemy\orm\mapper.py", line 3030, in configure_mappers
    raise e
sqlalchemy.exc.InvalidRequestError: One or more mappers failed to initialize - can't proceed with initialization of other mappers. Triggering mapper: 'Mapper|Chargetype|chargetype'. Original exception was: Could not determine join condition between parent/child tables on relationship Chargetype.charge_chargetype - there are no foreign keys linking these tables.  Ensure that referencing columns are associated with a ForeignKey or ForeignKeyConstraint, or specify a 'primaryjoin' expression.
2018-12-16 23:25:02,145 INFO: MicroJinn startup [in C:\MJP\micro\app\__init__.py:47]
2018-12-16 23:25:15,903 INFO: MicroJinn startup [in C:\MJP\micro\app\__init__.py:47]
2018-12-16 23:26:25,730 INFO: MicroJinn startup [in C:\MJP\micro\app\__init__.py:47]
2018-12-16 23:34:33,608 INFO: MicroJinn startup [in C:\MJP\micro\app\__init__.py:47]
2018-12-16 23:35:33,968 INFO: MicroJinn startup [in C:\MJP\micro\app\__init__.py:47]
2018-12-16 23:37:35,768 INFO: MicroJinn startup [in C:\MJP\micro\app\__init__.py:47]
2018-12-16 23:37:39,849 ERROR: Exception on /chargepage [GET] [in c:\mjp\micro\env\lib\site-packages\flask\app.py:1761]
Traceback (most recent call last):
  File "c:\mjp\micro\env\lib\site-packages\flask\app.py", line 2292, in wsgi_app
    response = self.full_dispatch_request()
  File "c:\mjp\micro\env\lib\site-packages\flask\app.py", line 1815, in full_dispatch_request
    rv = self.handle_user_exception(e)
  File "c:\mjp\micro\env\lib\site-packages\flask\app.py", line 1718, in handle_user_exception
    reraise(exc_type, exc_value, tb)
  File "c:\mjp\micro\env\lib\site-packages\flask\_compat.py", line 35, in reraise
    raise value
  File "c:\mjp\micro\env\lib\site-packages\flask\app.py", line 1813, in full_dispatch_request
    rv = self.dispatch_request()
  File "c:\mjp\micro\env\lib\site-packages\flask\app.py", line 1799, in dispatch_request
    return self.view_functions[rule.endpoint](**req.view_args)
  File "c:\mjp\micro\env\lib\site-packages\flask_login\utils.py", line 261, in decorated_view
    return func(*args, **kwargs)
TypeError: chargepage() missing 1 required positional argument: 'id'
2018-12-16 23:40:22,252 INFO: MicroJinn startup [in C:\MJP\micro\app\__init__.py:47]
